# Copyright (C) 2001-2018, Python Software Foundation
# For licence information, see README file.
#
msgid ""
msgstr ""
"Project-Id-Version: Python 3\n"
"Report-Msgid-Bugs-To: \n"
"POT-Creation-Date: 2019-11-15 18:54+0100\n"
"PO-Revision-Date: YEAR-MO-DA HO:MI+ZONE\n"
"Last-Translator: FULL NAME <EMAIL@ADDRESS>\n"
"Language-Team: FRENCH <traductions@lists.afpy.org>\n"
"Language: fr\n"
"MIME-Version: 1.0\n"
"Content-Type: text/plain; charset=UTF-8\n"
"Content-Transfer-Encoding: 8bit\n"

#: ../Doc/library/asyncio-exceptions.rst:8
msgid "Exceptions"
msgstr "Exceptions"

#: ../Doc/library/asyncio-exceptions.rst:10
msgid "**Source code:** :source:`Lib/asyncio/exceptions.py`"
msgstr ""

#: ../Doc/library/asyncio-exceptions.rst:16
#, fuzzy
msgid "The operation has exceeded the given deadline."
msgstr "L'opération a dépassé le délai donné."

#: ../Doc/library/asyncio-exceptions.rst:19
msgid ""
"This exception is different from the builtin :exc:`TimeoutError` exception."
msgstr ""

#: ../Doc/library/asyncio-exceptions.rst:25
msgid "The operation has been cancelled."
msgstr ""

#: ../Doc/library/asyncio-exceptions.rst:27
msgid ""
"This exception can be caught to perform custom operations when asyncio Tasks "
"are cancelled.  In almost all situations the exception must be re-raised."
msgstr ""

#: ../Doc/library/asyncio-exceptions.rst:33
msgid ":exc:`CancelledError` is now a subclass of :class:`BaseException`."
msgstr ""

#: ../Doc/library/asyncio-exceptions.rst:38
msgid "Invalid internal state of :class:`Task` or :class:`Future`."
msgstr ""

#: ../Doc/library/asyncio-exceptions.rst:40
msgid ""
"Can be raised in situations like setting a result value for a *Future* "
"object that already has a result value set."
msgstr ""

#: ../Doc/library/asyncio-exceptions.rst:46
msgid ""
"The \"sendfile\" syscall is not available for the given socket or file type."
msgstr ""

#: ../Doc/library/asyncio-exceptions.rst:49
msgid "A subclass of :exc:`RuntimeError`."
msgstr ""

#: ../Doc/library/asyncio-exceptions.rst:54
msgid "The requested read operation did not complete fully."
msgstr ""

#: ../Doc/library/asyncio-exceptions.rst:56
msgid "Raised by the :ref:`asyncio stream APIs<asyncio-streams>`."
msgstr ""

#: ../Doc/library/asyncio-exceptions.rst:58
msgid "This exception is a subclass of :exc:`EOFError`."
msgstr ""

#: ../Doc/library/asyncio-exceptions.rst:62
msgid "The total number (:class:`int`) of expected bytes."
msgstr ""

#: ../Doc/library/asyncio-exceptions.rst:66
msgid "A string of :class:`bytes` read before the end of stream was reached."
msgstr ""

#: ../Doc/library/asyncio-exceptions.rst:71
msgid "Reached the buffer size limit while looking for a separator."
msgstr ""

#: ../Doc/library/asyncio-exceptions.rst:73
msgid "Raised by the :ref:`asyncio stream APIs <asyncio-streams>`."
msgstr ""

#: ../Doc/library/asyncio-exceptions.rst:77
msgid "The total number of to be consumed bytes."
msgstr ""
